Workbook

Sheet Bid_Ask
F1: Term | G1: ATM | H1: ATM | I1: 25 RR | J1: 25 RR | K1: 25 BF | L1: 25 BF | M1: 10 RR | N1: 10 RR | O1: 10 BF | P1: 10 BF | R1: Term | S1: =G1 -> ATM | T1: =H1 -> ATM | U1: 25 Call USD | V1: 25 Call USD | W1: 25 Put USD | X1: 25 Put USD | Y1: 10 Call USD | Z1: 10 Call USD | AA1: 10 Put USD | AB1: 10 Put USD | AD1: =+R1 -> Term | AE1: ATM | AF1: 25 Call USD | AG1: 25 Put USD | AH1: 10 Call USD | AI1: 10 Put USD | AK1: Cuadre
A2: ATM | B2: 25 RR | C2: 25 BF | D2: 10 RR | E2: 10 BF | G2: Bid | H2: Ask | I2: Bid | J2: Ask | K2: Bid | L2: Ask | M2: Bid | N2: Ask | O2: Bid | P2: Ask | S2: =G2 -> Bid | T2: =H2 -> Ask | U2: Bid | V2: Ask | W2: Bid | X2: Ask | Y2: Bid | Z2: Ask | AA2: Bid | AB2: Ask | AE2: Mid | AF2: Mid | AG2: Mid | AH2: Mid | AI2: Mid
A3: USDCLPVON BGN Curncy | B3: USDCLP25RON BGN Curncy | C3: USDCLP25BON BGN Curncy | D3: USDCLP10RON BGN Curncy | E3: USDCLP10BON BGN Curncy | F3: 1D | G3: {=_xll.BDP($A3,G$2)} -> 13.48 | H3: {=_xll.BDP($A3,H$2)} -> 21.06 | I3: {=_xll.BDP($B3,I$2)} -> -1.265 | J3: {=_xll.BDP($B3,J$2)} -> 4.04 | K3: {=_xll.BDP($C3,K$2)} -> -1.615 | L3: {=_xll.BDP($C3,L$2)} -> 2.175 | M3: {=_xll.BDP($D3,M$2)} -> -1.91 | N3: {=_xll.BDP($D3,N$2)} -> 7.19 | O3: {=_xll.BDP($E3,O$2)} -> -2.08 | P3: {=_xll.BDP($E3,P$2)} -> 3.985 | R3: 1D | S3: =G3 -> 13.48 | T3: =H3 -> 21.06 | U3: =G3+I3*0.5+K3 -> 11.2325 | V3: =H3+J3*0.5+L3 -> 25.255 | W3: =G3-I3*0.5+K3 -> 12.4975 | X3: =H3-J3*0.5+L3 -> 21.215 | Y3: =G3+M3*0.5+O3 -> 10.445 | Z3: =H3+N3*0.5+P3 -> 28.64 | AA3: =G3-M3*0.5+O3 -> 12.355 | AB3: =H3-N3*0.5+P3 -> 21.45 | AD3: =+R3 -> 1D | AE3: =AVERAGE(S3:T3) -> 17.27 | AF3: =AVERAGE(U3:V3) -> 18.24375 | AG3: =AVERAGE(W3:X3) -> 16.85625 | AH3: =AVERAGE(Y3:Z3) -> 19.5425 | AI3: =AVERAGE(AA3:AB3) -> 16.9025 | AK3: =+AE3-'Mids BGN'!N3 -> 0 | AL3: =+AF3-'Mids BGN'!O3 -> 0 | AM3: =+AG3-'Mids BGN'!P3 -> 0 | AN3: =+AH3-'Mids BGN'!Q3 -> 0
A4: USDCLPV1W BGN Curncy | B4: USDCLP25R1W BGN Curncy | C4: USDCLP25B1W BGN Curncy | D4: USDCLP10R1W BGN Curncy | E4: USDCLP10B1W BGN Curncy | F4: 1W | G4: {=_xll.BDP($A4,G$2)} -> 10.95 | H4: {=_xll.BDP($A4,H$2)} -> 14.215 | I4: {=_xll.BDP($B4,I$2)} -> 0.455 | J4: {=_xll.BDP($B4,J$2)} -> 2.745 | K4: {=_xll.BDP($C4,K$2)} -> -0.515 | L4: {=_xll.BDP($C4,L$2)} -> 1.12 | M4: {=_xll.BDP($D4,M$2)} -> 1.1 | N4: {=_xll.BDP($D4,N$2)} -> 5.02 | O4: {=_xll.BDP($E4,O$2)} -> -0.285 | P4: {=_xll.BDP($E4,P$2)} -> 2.33 | R4: 1W | S4: =G4 -> 10.95 | T4: =H4 -> 14.215 | U4: =G4+I4*0.5+K4 -> 10.6625 | V4: =H4+J4*0.5+L4 -> 16.7075 | W4: =G4-I4*0.5+K4 -> 10.2075 | X4: =H4-J4*0.5+L4 -> 13.9625 | Y4: =G4+M4*0.5+O4 -> 11.215 | Z4: =H4+N4*0.5+P4 -> 19.055 | AA4: =G4-M4*0.5+O4 -> 10.115 | AB4: =H4-N4*0.5+P4 -> 14.035 | AD4: =+R4 -> 1W | AE4: =AVERAGE(S4:T4) -> 12.5825 | AF4: =AVERAGE(U4:V4) -> 13.685 | AG4: =AVERAGE(W4:X4) -> 12.085 | AH4: =AVERAGE(Y4:Z4) -> 15.135 | AI4: =AVERAGE(AA4:AB4) -> 12.075 | AK4: =+AE4-'Mids BGN'!N4 -> 0 | AL4: =+AF4-'Mids BGN'!O4 -> 0 | AM4: =+AG4-'Mids BGN'!P4 -> 0 | AN4: =+AH4-'Mids BGN'!Q4 -> 0
A5: USDCLPV2W BGN Curncy | B5: USDCLP25R2W BGN Curncy | C5: USDCLP25B2W BGN Curncy | D5: USDCLP10R2W BGN Curncy | E5: USDCLP10B2W BGN Curncy | F5: 2W | G5: {=_xll.BDP($A5,G$2)} -> 11.605 | H5: {=_xll.BDP($A5,H$2)} -> 14.21 | I5: {=_xll.BDP($B5,I$2)} -> 0.74 | J5: {=_xll.BDP($B5,J$2)} -> 2.565 | K5: {=_xll.BDP($C5,K$2)} -> -0.34 | L5: {=_xll.BDP($C5,L$2)} -> 0.965 | M5: {=_xll.BDP($D5,M$2)} -> 1.605 | N5: {=_xll.BDP($D5,N$2)} -> 4.735 | O5: {=_xll.BDP($E5,O$2)} -> -0.015 | P5: {=_xll.BDP($E5,P$2)} -> 2.07 | R5: 2W | S5: =G5 -> 11.605 | T5: =H5 -> 14.21 | U5: =G5+I5*0.5+K5 -> 11.635 | V5: =H5+J5*0.5+L5 -> 16.4575 | W5: =G5-I5*0.5+K5 -> 10.895 | X5: =H5-J5*0.5+L5 -> 13.8925 | Y5: =G5+M5*0.5+O5 -> 12.3925 | Z5: =H5+N5*0.5+P5 -> 18.6475 | AA5: =G5-M5*0.5+O5 -> 10.7875 | AB5: =H5-N5*0.5+P5 -> 13.9125 | AD5: =+R5 -> 2W | AE5: =AVERAGE(S5:T5) -> 12.9075 | AF5: =AVERAGE(U5:V5) -> 14.04625 | AG5: =AVERAGE(W5:X5) -> 12.39375 | AH5: =AVERAGE(Y5:Z5) -> 15.52 | AI5: =AVERAGE(AA5:AB5) -> 12.35 | AK5: =+AE5-'Mids BGN'!N5 -> 0 | AL5: =+AF5-'Mids BGN'!O5 -> 0 | AM5: =+AG5-'Mids BGN'!P5 -> 0 | AN5: =+AH5-'Mids BGN'!Q5 -> 0
A6: USDCLPV3W BGN Curncy | B6: USDCLP25R3W BGN Curncy | C6: USDCLP25B3W BGN Curncy | D6: USDCLP10R3W BGN Curncy | E6: USDCLP10B3W BGN Curncy | F6: 3W | G6: {=_xll.BDP($A6,G$2)} -> 11.89 | H6: {=_xll.BDP($A6,H$2)} -> 14.12 | I6: {=_xll.BDP($B6,I$2)} -> 0.945 | J6: {=_xll.BDP($B6,J$2)} -> 2.505 | K6: {=_xll.BDP($C6,K$2)} -> -0.23 | L6: {=_xll.BDP($C6,L$2)} -> 0.885 | M6: {=_xll.BDP($D6,M$2)} -> 1.97 | N6: {=_xll.BDP($D6,N$2)} -> 4.645 | O6: {=_xll.BDP($E6,O$2)} -> 0.165 | P6: {=_xll.BDP($E6,P$2)} -> 1.95 | R6: 3W | S6: =G6 -> 11.89 | T6: =H6 -> 14.12 | U6: =G6+I6*0.5+K6 -> 12.1325 | V6: =H6+J6*0.5+L6 -> 16.2575 | W6: =G6-I6*0.5+K6 -> 11.1875 | X6: =H6-J6*0.5+L6 -> 13.7525 | Y6: =G6+M6*0.5+O6 -> 13.04 | Z6: =H6+N6*0.5+P6 -> 18.3925 | AA6: =G6-M6*0.5+O6 -> 11.07 | AB6: =H6-N6*0.5+P6 -> 13.7475 | AD6: =+R6 -> 3W | AE6: =AVERAGE(S6:T6) -> 13.005 | AF6: =AVERAGE(U6:V6) -> 14.195 | AG6: =AVERAGE(W6:X6) -> 12.47 | AH6: =AVERAGE(Y6:Z6) -> 15.71625 | AI6: =AVERAGE(AA6:AB6) -> 12.40875 | AK6: =+AE6-'Mids BGN'!N6 -> 0 | AL6: =+AF6-'Mids BGN'!O6 -> 0 | AM6: =+AG6-'Mids BGN'!P6 -> 0 | AN6: =+AH6-'Mids BGN'!Q6 -> 0
A7: USDCLPV1M BGN Curncy | B7: USDCLP25R1M BGN Curncy | C7: USDCLP25B1M BGN Curncy | D7: USDCLP10R1M BGN Curncy | E7: USDCLP10B1M BGN Curncy | F7: 1M | G7: {=_xll.BDP($A7,G$2)} -> 12.27 | H7: {=_xll.BDP($A7,H$2)} -> 13.76 | I7: {=_xll.BDP($B7,I$2)} -> 1.26 | J7: {=_xll.BDP($B7,J$2)} -> 2.305 | K7: {=_xll.BDP($C7,K$2)} -> -0.03 | L7: {=_xll.BDP($C7,L$2)} -> 0.715 | M7: {=_xll.BDP($D7,M$2)} -> 2.53 | N7: {=_xll.BDP($D7,N$2)} -> 4.32 | O7: {=_xll.BDP($E7,O$2)} -> 0.485 | P7: {=_xll.BDP($E7,P$2)} -> 1.68 | R7: 1M | S7: =G7 -> 12.27 | T7: =H7 -> 13.76 | U7: =G7+I7*0.5+K7 -> 12.87 | V7: =H7+J7*0.5+L7 -> 15.6275 | W7: =G7-I7*0.5+K7 -> 11.61 | X7: =H7-J7*0.5+L7 -> 13.3225 | Y7: =G7+M7*0.5+O7 -> 14.02 | Z7: =H7+N7*0.5+P7 -> 17.6 | AA7: =G7-M7*0.5+O7 -> 11.49 | AB7: =H7-N7*0.5+P7 -> 13.28 | AD7: =+R7 -> 1M | AE7: =AVERAGE(S7:T7) -> 13.015 | AF7: =AVERAGE(U7:V7) -> 14.24875 | AG7: =AVERAGE(W7:X7) -> 12.46625 | AH7: =AVERAGE(Y7:Z7) -> 15.81 | AI7: =AVERAGE(AA7:AB7) -> 12.385 | AK7: =+AE7-'Mids BGN'!N7 -> 0.005 | AL7: =+AF7-'Mids BGN'!O7 -> 0.005 | AM7: =+AG7-'Mids BGN'!P7 -> 0.005 | AN7: =+AH7-'Mids BGN'!Q7 -> 0.005
A8: USDCLPV2M BGN Curncy | B8: USDCLP25R2M BGN Curncy | C8: USDCLP25B2M BGN Curncy | D8: USDCLP10R2M BGN Curncy | E8: USDCLP10B2M BGN Curncy | F8: 2M | G8: {=_xll.BDP($A8,G$2)} -> 12.14 | H8: {=_xll.BDP($A8,H$2)} -> 13.63 | I8: {=_xll.BDP($B8,I$2)} -> 1.305 | J8: {=_xll.BDP($B8,J$2)} -> 2.355 | K8: {=_xll.BDP($C8,K$2)} -> -0.015 | L8: {=_xll.BDP($C8,L$2)} -> 0.735 | M8: {=_xll.BDP($D8,M$2)} -> 2.635 | N8: {=_xll.BDP($D8,N$2)} -> 4.435 | O8: {=_xll.BDP($E8,O$2)} -> 0.5 | P8: {=_xll.BDP($E8,P$2)} -> 1.7 | R8: 2M | S8: =G8 -> 12.14 | T8: =H8 -> 13.63 | U8: =G8+I8*0.5+K8 -> 12.7775 | V8: =H8+J8*0.5+L8 -> 15.5425 | W8: =G8-I8*0.5+K8 -> 11.4725 | X8: =H8-J8*0.5+L8 -> 13.1875 | Y8: =G8+M8*0.5+O8 -> 13.9575 | Z8: =H8+N8*0.5+P8 -> 17.5475 | AA8: =G8-M8*0.5+O8 -> 11.3225 | AB8: =H8-N8*0.5+P8 -> 13.1125 | AD8: =+R8 -> 2M | AE8: =AVERAGE(S8:T8) -> 12.885 | AF8: =AVERAGE(U8:V8) -> 14.16 | AG8: =AVERAGE(W8:X8) -> 12.33 | AH8: =AVERAGE(Y8:Z8) -> 15.7525 | AI8: =AVERAGE(AA8:AB8) -> 12.2175 | AK8: =+AE8-'Mids BGN'!N8 -> 0.005 | AL8: =+AF8-'Mids BGN'!O8 -> 0.005 | AM8: =+AG8-'Mids BGN'!P8 -> 0.005 | AN8: =+AH8-'Mids BGN'!Q8 -> 0.005
A9: USDCLPV3M BGN Curncy | B9: USDCLP25R3M BGN Curncy | C9: USDCLP25B3M BGN Curncy | D9: USDCLP10R3M BGN Curncy | E9: USDCLP10B3M BGN Curncy | F9: 3M | G9: {=_xll.BDP($A9,G$2)} -> 12.24 | H9: {=_xll.BDP($A9,H$2)} -> 13.24 | I9: {=_xll.BDP($B9,I$2)} -> 1.525 | J9: {=_xll.BDP($B9,J$2)} -> 2.23 | K9: {=_xll.BDP($C9,K$2)} -> 0.135 | L9: {=_xll.BDP($C9,L$2)} -> 0.635 | M9: {=_xll.BDP($D9,M$2)} -> 3.045 | N9: {=_xll.BDP($D9,N$2)} -> 4.25 | O9: {=_xll.BDP($E9,O$2)} -> 0.75 | P9: {=_xll.BDP($E9,P$2)} -> 1.55 | R9: 3M | S9: =G9 -> 12.24 | T9: =H9 -> 13.24 | U9: =G9+I9*0.5+K9 -> 13.1375 | V9: =H9+J9*0.5+L9 -> 14.99 | W9: =G9-I9*0.5+K9 -> 11.6125 | X9: =H9-J9*0.5+L9 -> 12.76 | Y9: =G9+M9*0.5+O9 -> 14.5125 | Z9: =H9+N9*0.5+P9 -> 16.915 | AA9: =G9-M9*0.5+O9 -> 11.4675 | AB9: =H9-N9*0.5+P9 -> 12.665 | AD9: =+R9 -> 3M | AE9: =AVERAGE(S9:T9) -> 12.74 | AF9: =AVERAGE(U9:V9) -> 14.06375 | AG9: =AVERAGE(W9:X9) -> 12.18625 | AH9: =AVERAGE(Y9:Z9) -> 15.71375 | AI9: =AVERAGE(AA9:AB9) -> 12.06625 | AK9: =+AE9-'Mids BGN'!N9 -> 0 | AL9: =+AF9-'Mids BGN'!O9 -> 0 | AM9: =+AG9-'Mids BGN'!P9 -> 0 | AN9: =+AH9-'Mids BGN'!Q9 -> 0
A10: USDCLPV4M BGN Curncy | B10: USDCLP25R4M BGN Curncy | C10: USDCLP25B4M BGN Curncy | D10: USDCLP10R4M BGN Curncy | E10: USDCLP10B4M BGN Curncy | F10: 4M | G10: {=_xll.BDP($A10,G$2)} -> 12.09 | H10: {=_xll.BDP($A10,H$2)} -> 13.075 | I10: {=_xll.BDP($B10,I$2)} -> 1.565 | J10: {=_xll.BDP($B10,J$2)} -> 2.255 | K10: {=_xll.BDP($C10,K$2)} -> 0.16 | L10: {=_xll.BDP($C10,L$2)} -> 0.655 | M10: {=_xll.BDP($D10,M$2)} -> 3.135 | N10: {=_xll.BDP($D10,N$2)} -> 4.32 | O10: {=_xll.BDP($E10,O$2)} -> 0.805 | P10: {=_xll.BDP($E10,P$2)} -> 1.595 | R10: 4M | S10: =G10 -> 12.09 | T10: =H10 -> 13.075 | U10: =G10+I10*0.5+K10 -> 13.0325 | V10: =H10+J10*0.5+L10 -> 14.8575 | W10: =G10-I10*0.5+K10 -> 11.4675 | X10: =H10-J10*0.5+L10 -> 12.6025 | Y10: =G10+M10*0.5+O10 -> 14.4625 | Z10: =H10+N10*0.5+P10 -> 16.83 | AA10: =G10-M10*0.5+O10 -> 11.3275 | AB10: =H10-N10*0.5+P10 -> 12.51 | AD10: =+R10 -> 4M | AE10: =AVERAGE(S10:T10) -> 12.5825 | AF10: =AVERAGE(U10:V10) -> 13.945 | AG10: =AVERAGE(W10:X10) -> 12.035 | AH10: =AVERAGE(Y10:Z10) -> 15.64625 | AI10: =AVERAGE(AA10:AB10) -> 11.91875 | AK10: =+AE10-'Mids BGN'!N10 -> 0 | AL10: =+AF10-'Mids BGN'!O10 -> 0 | AM10: =+AG10-'Mids BGN'!P10 -> 0 | AN10: =+AH10-'Mids BGN'!Q10 -> 0
A11: USDCLPV6M BGN Curncy | B11: USDCLP25R6M BGN Curncy | C11: USDCLP25B6M BGN Curncy | D11: USDCLP10R6M BGN Curncy | E11: USDCLP10B6M BGN Curncy | F11: 6M | G11: {=_xll.BDP($A11,G$2)} -> 11.95 | H11: {=_xll.BDP($A11,H$2)} -> 12.94 | I11: {=_xll.BDP($B11,I$2)} -> 1.59 | J11: {=_xll.BDP($B11,J$2)} -> 2.285 | K11: {=_xll.BDP($C11,K$2)} -> 0.185 | L11: {=_xll.BDP($C11,L$2)} -> 0.68 | M11: {=_xll.BDP($D11,M$2)} -> 3.21 | N11: {=_xll.BDP($D11,N$2)} -> 4.4 | O11: {=_xll.BDP($E11,O$2)} -> 0.86 | P11: {=_xll.BDP($E11,P$2)} -> 1.655 | R11: 6M | S11: =G11 -> 11.95 | T11: =H11 -> 12.94 | U11: =G11+I11*0.5+K11 -> 12.93 | V11: =H11+J11*0.5+L11 -> 14.7625 | W11: =G11-I11*0.5+K11 -> 11.34 | X11: =H11-J11*0.5+L11 -> 12.4775 | Y11: =G11+M11*0.5+O11 -> 14.415 | Z11: =H11+N11*0.5+P11 -> 16.795 | AA11: =G11-M11*0.5+O11 -> 11.205 | AB11: =H11-N11*0.5+P11 -> 12.395 | AD11: =+R11 -> 6M | AE11: =AVERAGE(S11:T11) -> 12.445 | AF11: =AVERAGE(U11:V11) -> 13.84625 | AG11: =AVERAGE(W11:X11) -> 11.90875 | AH11: =AVERAGE(Y11:Z11) -> 15.605 | AI11: =AVERAGE(AA11:AB11) -> 11.8 | AK11: =+AE11-'Mids BGN'!N11 -> -0.005 | AL11: =+AF11-'Mids BGN'!O11 -> -0.005 | AM11: =+AG11-'Mids BGN'!P11 -> -0.005 | AN11: =+AH11-'Mids BGN'!Q11 -> -0.005
A12: USDCLPV9M BGN Curncy | B12: USDCLP25R9M BGN Curncy | C12: USDCLP25B9M BGN Curncy | D12: USDCLP10R9M BGN Curncy | E12: USDCLP10B9M BGN Curncy | F12: 9M | G12: {=_xll.BDP($A12,G$2)} -> 11.99 | H12: {=_xll.BDP($A12,H$2)} -> 12.87 | I12: {=_xll.BDP($B12,I$2)} -> 1.655 | J12: {=_xll.BDP($B12,J$2)} -> 2.265 | K12: {=_xll.BDP($C12,K$2)} -> 0.245 | L12: {=_xll.BDP($C12,L$2)} -> 0.685 | M12: {=_xll.BDP($D12,M$2)} -> 3.355 | N12: {=_xll.BDP($D12,N$2)} -> 4.405 | O12: {=_xll.BDP($E12,O$2)} -> 0.96 | P12: {=_xll.BDP($E12,P$2)} -> 1.66 | R12: 9M | S12: =G12 -> 11.99 | T12: =H12 -> 12.87 | U12: =G12+I12*0.5+K12 -> 13.0625 | V12: =H12+J12*0.5+L12 -> 14.6875 | W12: =G12-I12*0.5+K12 -> 11.4075 | X12: =H12-J12*0.5+L12 -> 12.4225 | Y12: =G12+M12*0.5+O12 -> 14.6275 | Z12: =H12+N12*0.5+P12 -> 16.7325 | AA12: =G12-M12*0.5+O12 -> 11.2725 | AB12: =H12-N12*0.5+P12 -> 12.3275 | AD12: =+R12 -> 9M | AE12: =AVERAGE(S12:T12) -> 12.43 | AF12: =AVERAGE(U12:V12) -> 13.875 | AG12: =AVERAGE(W12:X12) -> 11.915 | AH12: =AVERAGE(Y12:Z12) -> 15.68 | AI12: =AVERAGE(AA12:AB12) -> 11.8 | AK12: =+AE12-'Mids BGN'!N12 -> 0 | AL12: =+AF12-'Mids BGN'!O12 -> 0 | AM12: =+AG12-'Mids BGN'!P12 -> 0 | AN12: =+AH12-'Mids BGN'!Q12 -> 0
A13: USDCLPV1Y BGN Curncy | B13: USDCLP25R1Y BGN Curncy | C13: USDCLP25B1Y BGN Curncy | D13: USDCLP10R1Y BGN Curncy | E13: USDCLP10B1Y BGN Curncy | F13: 1Y | G13: {=_xll.BDP($A13,G$2)} -> 11.92 | H13: {=_xll.BDP($A13,H$2)} -> 12.79 | I13: {=_xll.BDP($B13,I$2)} -> 1.66 | J13: {=_xll.BDP($B13,J$2)} -> 2.275 | K13: {=_xll.BDP($C13,K$2)} -> 0.27 | L13: {=_xll.BDP($C13,L$2)} -> 0.71 | M13: {=_xll.BDP($D13,M$2)} -> 3.42 | N13: {=_xll.BDP($D13,N$2)} -> 4.47 | O13: {=_xll.BDP($E13,O$2)} -> 1.01 | P13: {=_xll.BDP($E13,P$2)} -> 1.71 | R13: 1Y | S13: =G13 -> 11.92 | T13: =H13 -> 12.79 | U13: =G13+I13*0.5+K13 -> 13.02 | V13: =H13+J13*0.5+L13 -> 14.6375 | W13: =G13-I13*0.5+K13 -> 11.36 | X13: =H13-J13*0.5+L13 -> 12.3625 | Y13: =G13+M13*0.5+O13 -> 14.64 | Z13: =H13+N13*0.5+P13 -> 16.735 | AA13: =G13-M13*0.5+O13 -> 11.22 | AB13: =H13-N13*0.5+P13 -> 12.265 | AD13: =+R13 -> 1Y | AE13: =AVERAGE(S13:T13) -> 12.355 | AF13: =AVERAGE(U13:V13) -> 13.82875 | AG13: =AVERAGE(W13:X13) -> 11.86125 | AH13: =AVERAGE(Y13:Z13) -> 15.6875 | AI13: =AVERAGE(AA13:AB13) -> 11.7425 | AK13: =+AE13-'Mids BGN'!N13 -> -0.005 | AL13: =+AF13-'Mids BGN'!O13 -> -0.005 | AM13: =+AG13-'Mids BGN'!P13 -> -0.005 | AN13: =+AH13-'Mids BGN'!Q13 -> -0.005
A14: USDCLPV18M BGN Curncy | B14: USDCLP25R18M BGN Curncy | C14: USDCLP25B18M BGN Curncy | D14: USDCLP10R18M BGN Curncy | E14: USDCLP10B18M BGN Curncy | F14: 18M | G14: {=_xll.BDP($A14,G$2)} -> 12.13 | H14: {=_xll.BDP($A14,H$2)} -> 13.07 | I14: {=_xll.BDP($B14,I$2)} -> 1.645 | J14: {=_xll.BDP($B14,J$2)} -> 2.305 | K14: {=_xll.BDP($C14,K$2)} -> 0.32 | L14: {=_xll.BDP($C14,L$2)} -> 0.795 | M14: {=_xll.BDP($D14,M$2)} -> 3.38 | N14: {=_xll.BDP($D14,N$2)} -> 4.52 | O14: {=_xll.BDP($E14,O$2)} -> 1.11 | P14: {=_xll.BDP($E14,P$2)} -> 1.865 | R14: 18M | S14: =G14 -> 12.13 | T14: =H14 -> 13.07 | U14: =G14+I14*0.5+K14 -> 13.2725 | V14: =H14+J14*0.5+L14 -> 15.0175 | W14: =G14-I14*0.5+K14 -> 11.6275 | X14: =H14-J14*0.5+L14 -> 12.7125 | Y14: =G14+M14*0.5+O14 -> 14.93 | Z14: =H14+N14*0.5+P14 -> 17.195 | AA14: =G14-M14*0.5+O14 -> 11.55 | AB14: =H14-N14*0.5+P14 -> 12.675 | AD14: =+R14 -> 18M | AE14: =AVERAGE(S14:T14) -> 12.6 | AF14: =AVERAGE(U14:V14) -> 14.145 | AG14: =AVERAGE(W14:X14) -> 12.17 | AH14: =AVERAGE(Y14:Z14) -> 16.0625 | AI14: =AVERAGE(AA14:AB14) -> 12.1125 | AK14: =+AE14-'Mids BGN'!N14 -> 0 | AL14: =+AF14-'Mids BGN'!O14 -> 0 | AM14: =+AG14-'Mids BGN'!P14 -> 0 | AN14: =+AH14-'Mids BGN'!Q14 -> 0
... A21: USDCLPV15Y BGN Curncy | B21: USDCLP25R15Y BGN Curncy | C21: USDCLP25B15Y BGN Curncy | D21: USDCLP10R15Y BGN Curncy | E21: USDCLP10B15Y BGN Curncy | F21: 15Y | G21: {=_xll.BDP($A21,G$2)} -> 9.39 | H21: {=_xll.BDP($A21,H$2)} -> 13.26 | I21: {=_xll.BDP($B21,I$2)} -> 0.425 | J21: {=_xll.BDP($B21,J$2)} -> 3.135 | K21: {=_xll.BDP($C21,K$2)} -> -0.19 | L21: {=_xll.BDP($C21,L$2)} -> 1.745 | M21: {=_xll.BDP($D21,M$2)} -> 1.56 | N21: {=_xll.BDP($D21,N$2)} -> 6.2 | O21: {=_xll.BDP($E21,O$2)} -> 0.66 | P21: {=_xll.BDP($E21,P$2)} -> 3.755 | R21: 15Y | S21: =G21 -> 9.39 | T21: =H21 -> 13.26 | U21: =G21+I21*0.5+K21 -> 9.4125 | V21: =H21+J21*0.5+L21 -> 16.5725 | W21: =G21-I21*0.5+K21 -> 8.9875 | X21: =H21-J21*0.5+L21 -> 13.4375 | Y21: =G21+M21*0.5+O21 -> 10.83 | Z21: =H21+N21*0.5+P21 -> 20.115 | AA21: =G21-M21*0.5+O21 -> 9.27 | AB21: =H21-N21*0.5+P21 -> 13.915 | AD21: =+R21 -> 15Y | AE21: =AVERAGE(S21:T21) -> 11.325 | AF21: =AVERAGE(U21:V21) -> 12.9925 | AG21: =AVERAGE(W21:X21) -> 11.2125 | AH21: =AVERAGE(Y21:Z21) -> 15.4725 | AI21: =AVERAGE(AA21:AB21) -> 11.5925 | AK21: =+AE21-'Mids BGN'!N21 -> 0 | AL21: =+AF21-'Mids BGN'!O21 -> 0 | AM21: =+AG21-'Mids BGN'!P21 -> 0 | AN21: =+AH21-'Mids BGN'!Q21 -> 0

Sheet Mids BGN
F1: Term | G1: ATM | H1: 25 RR | I1: 25 BF | J1: 10 RR | K1: 10 BF | M1: Term | N1: =+G1 -> ATM | O1: 25 Call USD | P1: 25 Put USD | Q1: 10 Call USD | R1: 10 Put USD
A2: ATM | B2: 25 RR | C2: 25 BF | D2: 10 RR | E2: 10 BF | G2: Mid | H2: Mid | I2: Mid | J2: Mid | K2: Mid | N2: =+G2 -> Mid | O2: Mid | P2: Mid | Q2: Mid | R2: Mid
A3: USDCLPVON BGN Curncy | B3: USDCLP25RON BGN Curncy | C3: USDCLP25BON BGN Curncy | D3: USDCLP10RON BGN Curncy | E3: USDCLP10BON BGN Curncy | F3: 1D | G3: {=_xll.BDP($A3,G$2)} -> 17.27 | H3: {=_xll.BDP($B3,H$2)} -> 1.3875 | I3: {=_xll.BDP($C3,I$2)} -> 0.28 | J3: {=_xll.BDP($D3,J$2)} -> 2.64 | K3: {=_xll.BDP($E3,K$2)} -> 0.9525 | M3: 1D | N3: =+G3 -> 17.27 | O3: =G3+H3*0.5+I3 -> 18.24375 | P3: =G3-H3*0.5+I3 -> 16.85625 | Q3: =G3+J3*0.5+K3 -> 19.5425 | R3: =G3-J3*0.5+K3 -> 16.9025
A4: USDCLPV1W BGN Curncy | B4: USDCLP25R1W BGN Curncy | C4: USDCLP25B1W BGN Curncy | D4: USDCLP10R1W BGN Curncy | E4: USDCLP10B1W BGN Curncy | F4: 1W | G4: {=_xll.BDP($A4,G$2)} -> 12.5825 | H4: {=_xll.BDP($B4,H$2)} -> 1.6 | I4: {=_xll.BDP($C4,I$2)} -> 0.3025 | J4: {=_xll.BDP($D4,J$2)} -> 3.06 | K4: {=_xll.BDP($E4,K$2)} -> 1.0225 | M4: 1W | N4: =+G4 -> 12.5825 | O4: =G4+H4*0.5+I4 -> 13.685 | P4: =G4-H4*0.5+I4 -> 12.085 | Q4: =G4+J4*0.5+K4 -> 15.135 | R4: =G4-J4*0.5+K4 -> 12.075
A5: USDCLPV2W BGN Curncy | B5: USDCLP25R2W BGN Curncy | C5: USDCLP25B2W BGN Curncy | D5: USDCLP10R2W BGN Curncy | E5: USDCLP10B2W BGN Curncy | F5: 2W | G5: {=_xll.BDP($A5,G$2)} -> 12.9075 | H5: {=_xll.BDP($B5,H$2)} -> 1.6525 | I5: {=_xll.BDP($C5,I$2)} -> 0.3125 | J5: {=_xll.BDP($D5,J$2)} -> 3.17 | K5: {=_xll.BDP($E5,K$2)} -> 1.0275 | M5: 2W | N5: =+G5 -> 12.9075 | O5: =G5+H5*0.5+I5 -> 14.04625 | P5: =G5-H5*0.5+I5 -> 12.39375 | Q5: =G5+J5*0.5+K5 -> 15.52 | R5: =G5-J5*0.5+K5 -> 12.35
A6: USDCLPV3W BGN Curncy | B6: USDCLP25R3W BGN Curncy | C6: USDCLP25B3W BGN Curncy | D6: USDCLP10R3W BGN Curncy | E6: USDCLP10B3W BGN Curncy | F6: 3W | G6: {=_xll.BDP($A6,G$2)} -> 13.005 | H6: {=_xll.BDP($B6,H$2)} -> 1.725 | I6: {=_xll.BDP($C6,I$2)} -> 0.3275 | J6: {=_xll.BDP($D6,J$2)} -> 3.3075 | K6: {=_xll.BDP($E6,K$2)} -> 1.0575 | M6: 3W | N6: =+G6 -> 13.005 | O6: =G6+H6*0.5+I6 -> 14.195 | P6: =G6-H6*0.5+I6 -> 12.47 | Q6: =G6+J6*0.5+K6 -> 15.71625 | R6: =G6-J6*0.5+K6 -> 12.40875
A7: USDCLPV1M BGN Curncy | B7: USDCLP25R1M BGN Curncy | C7: USDCLP25B1M BGN Curncy | D7: USDCLP10R1M BGN Curncy | E7: USDCLP10B1M BGN Curncy | F7: 1M | G7: {=_xll.BDP($A7,G$2)} -> 13.01 | H7: {=_xll.BDP($B7,H$2)} -> 1.7825 | I7: {=_xll.BDP($C7,I$2)} -> 0.3425 | J7: {=_xll.BDP($D7,J$2)} -> 3.425 | K7: {=_xll.BDP($E7,K$2)} -> 1.0825 | M7: 1M | N7: =+G7 -> 13.01 | O7: =G7+H7*0.5+I7 -> 14.24375 | P7: =G7-H7*0.5+I7 -> 12.46125 | Q7: =G7+J7*0.5+K7 -> 15.805 | R7: =G7-J7*0.5+K7 -> 12.38
A8: USDCLPV2M BGN Curncy | B8: USDCLP25R2M BGN Curncy | C8: USDCLP25B2M BGN Curncy | D8: USDCLP10R2M BGN Curncy | E8: USDCLP10B2M BGN Curncy | F8: 2M | G8: {=_xll.BDP($A8,G$2)} -> 12.88 | H8: {=_xll.BDP($B8,H$2)} -> 1.83 | I8: {=_xll.BDP($C8,I$2)} -> 0.36 | J8: {=_xll.BDP($D8,J$2)} -> 3.535 | K8: {=_xll.BDP($E8,K$2)} -> 1.1 | M8: 2M | N8: =+G8 -> 12.88 | O8: =G8+H8*0.5+I8 -> 14.155 | P8: =G8-H8*0.5+I8 -> 12.325 | Q8: =G8+J8*0.5+K8 -> 15.7475 | R8: =G8-J8*0.5+K8 -> 12.2125
A9: USDCLPV3M BGN Curncy | B9: USDCLP25R3M BGN Curncy | C9: USDCLP25B3M BGN Curncy | D9: USDCLP10R3M BGN Curncy | E9: USDCLP10B3M BGN Curncy | F9: 3M | G9: {=_xll.BDP($A9,G$2)} -> 12.74 | H9: {=_xll.BDP($B9,H$2)} -> 1.8775 | I9: {=_xll.BDP($C9,I$2)} -> 0.385 | J9: {=_xll.BDP($D9,J$2)} -> 3.6475 | K9: {=_xll.BDP($E9,K$2)} -> 1.15 | M9: 3M | N9: =+G9 -> 12.74 | O9: =G9+H9*0.5+I9 -> 14.06375 | P9: =G9-H9*0.5+I9 -> 12.18625 | Q9: =G9+J9*0.5+K9 -> 15.71375 | R9: =G9-J9*0.5+K9 -> 12.06625
A10: USDCLPV4M BGN Curncy | B10: USDCLP25R4M BGN Curncy | C10: USDCLP25B4M BGN Curncy | D10: USDCLP10R4M BGN Curncy | E10: USDCLP10B4M BGN Curncy | F10: 4M | G10: {=_xll.BDP($A10,G$2)} -> 12.5825 | H10: {=_xll.BDP($B10,H$2)} -> 1.91 | I10: {=_xll.BDP($C10,I$2)} -> 0.4075 | J10: {=_xll.BDP($D10,J$2)} -> 3.7275 | K10: {=_xll.BDP($E10,K$2)} -> 1.2 | M10: 4M | N10: =+G10 -> 12.5825 | O10: =G10+H10*0.5+I10 -> 13.945 | P10: =G10-H10*0.5+I10 -> 12.035 | Q10: =G10+J10*0.5+K10 -> 15.64625 | R10: =G10-J10*0.5+K10 -> 11.91875
A11: USDCLPV6M BGN Curncy | B11: USDCLP25R6M BGN Curncy | C11: USDCLP25B6M BGN Curncy | D11: USDCLP10R6M BGN Curncy | E11: USDCLP10B6M BGN Curncy | F11: 6M | G11: {=_xll.BDP($A11,G$2)} -> 12.45 | H11: {=_xll.BDP($B11,H$2)} -> 1.9375 | I11: {=_xll.BDP($C11,I$2)} -> 0.4325 | J11: {=_xll.BDP($D11,J$2)} -> 3.805 | K11: {=_xll.BDP($E11,K$2)} -> 1.2575 | M11: 6M | N11: =+G11 -> 12.45 | O11: =G11+H11*0.5+I11 -> 13.85125 | P11: =G11-H11*0.5+I11 -> 11.91375 | Q11: =G11+J11*0.5+K11 -> 15.61 | R11: =G11-J11*0.5+K11 -> 11.805
A12: USDCLPV9M BGN Curncy | B12: USDCLP25R9M BGN Curncy | C12: USDCLP25B9M BGN Curncy | D12: USDCLP10R9M BGN Curncy | E12: USDCLP10B9M BGN Curncy | F12: 9M | G12: {=_xll.BDP($A12,G$2)} -> 12.43 | H12: {=_xll.BDP($B12,H$2)} -> 1.96 | I12: {=_xll.BDP($C12,I$2)} -> 0.465 | J12: {=_xll.BDP($D12,J$2)} -> 3.88 | K12: {=_xll.BDP($E12,K$2)} -> 1.31 | M12: 9M | N12: =+G12 -> 12.43 | O12: =G12+H12*0.5+I12 -> 13.875 | P12: =G12-H12*0.5+I12 -> 11.915 | Q12: =G12+J12*0.5+K12 -> 15.68 | R12: =G12-J12*0.5+K12 -> 11.8
A13: USDCLPV1Y BGN Curncy | B13: USDCLP25R1Y BGN Curncy | C13: USDCLP25B1Y BGN Curncy | D13: USDCLP10R1Y BGN Curncy | E13: USDCLP10B1Y BGN Curncy | F13: 1Y | G13: {=_xll.BDP($A13,G$2)} -> 12.36 | H13: {=_xll.BDP($B13,H$2)} -> 1.9675 | I13: {=_xll.BDP($C13,I$2)} -> 0.49 | J13: {=_xll.BDP($D13,J$2)} -> 3.945 | K13: {=_xll.BDP($E13,K$2)} -> 1.36 | M13: 1Y | N13: =+G13 -> 12.36 | O13: =G13+H13*0.5+I13 -> 13.83375 | P13: =G13-H13*0.5+I13 -> 11.86625 | Q13: =G13+J13*0.5+K13 -> 15.6925 | R13: =G13-J13*0.5+K13 -> 11.7475
A14: USDCLPV18M BGN Curncy | B14: USDCLP25R18M BGN Curncy | C14: USDCLP25B18M BGN Curncy | D14: USDCLP10R18M BGN Curncy | E14: USDCLP10B18M BGN Curncy | F14: 18M | G14: {=_xll.BDP($A14,G$2)} -> 12.6 | H14: {=_xll.BDP($B14,H$2)} -> 1.975 | I14: {=_xll.BDP($C14,I$2)} -> 0.5575 | J14: {=_xll.BDP($D14,J$2)} -> 3.95 | K14: {=_xll.BDP($E14,K$2)} -> 1.4875 | M14: 18M | N14: =+G14 -> 12.6 | O14: =G14+H14*0.5+I14 -> 14.145 | P14: =G14-H14*0.5+I14 -> 12.17 | Q14: =G14+J14*0.5+K14 -> 16.0625 | R14: =G14-J14*0.5+K14 -> 12.1125
... A21: USDCLPV15Y BGN Curncy | B21: USDCLP25R15Y BGN Curncy | C21: USDCLP25B15Y BGN Curncy | D21: USDCLP10R15Y BGN Curncy | E21: USDCLP10B15Y BGN Curncy | F21: 15Y | G21: {=_xll.BDP($A21,G$2)} -> 11.325 | H21: {=_xll.BDP($B21,H$2)} -> 1.78 | I21: {=_xll.BDP($C21,I$2)} -> 0.7775 | J21: {=_xll.BDP($D21,J$2)} -> 3.88 | K21: {=_xll.BDP($E21,K$2)} -> 2.2075 | M21: 15Y | N21: =+G21 -> 11.325 | O21: =G21+H21*0.5+I21 -> 12.9925 | P21: =G21-H21*0.5+I21 -> 11.2125 | Q21: =G21+J21*0.5+K21 -> 15.4725 | R21: =G21-J21*0.5+K21 -> 11.5925
T28: 16.746 | U28: 26.694 | V28: 15.439 | W28: 24.471 | X28: =+V28-T28 -> -1.307 | Y28: =+W28-U28 -> -2.223

Sheet Mids GFI
F1: Term | G1: ATM | H1: 25 RR | I1: 25 BF | J1: 10 RR | K1: 10 BF | M1: Term | N1: =+G1 -> ATM | O1: 25 Call USD | P1: 25 Put USD | Q1: 10 Call USD | R1: 10 Put USD
A2: ATM | B2: 25 RR | C2: 25 BF | D2: 10 RR | E2: 10 BF | G2: Mid | H2: Mid | I2: Mid | J2: Mid | K2: Mid | N2: =+G2 -> Mid | O2: Mid | P2: Mid | Q2: Mid | R2: Mid
A3: USDCLPVON GFFX Curncy | B3: USDCLP25RON GFFX Curncy | C3: USDCLP25BON GFFX Curncy | D3: USDCLP10RON GFFX Curncy | E3: USDCLP10BON GFFX Curncy | F3: 1D | G3: {=_xll.BDP($A3,G$2)} -> 13.71 | H3: {=_xll.BDP($B3,H$2)} -> 0.82 | I3: {=_xll.BDP($C3,I$2)} -> 0.21 | J3: {=_xll.BDP($D3,J$2)} -> 1.59 | K3: {=_xll.BDP($E3,K$2)} -> 0.79 | M3: 1D | N3: =+G3 -> 13.71 | O3: =G3+H3*0.5+I3 -> 14.33 | P3: =G3-H3*0.5+I3 -> 13.51 | Q3: =G3+J3*0.5+K3 -> 15.295 | R3: =G3-J3*0.5+K3 -> 13.705
A4: USDCLPV1W GFFX Curncy | B4: USDCLP25R1W GFFX Curncy | C4: USDCLP25B1W GFFX Curncy | D4: USDCLP10R1W GFFX Curncy | E4: USDCLP10B1W GFFX Curncy | F4: 1W | G4: {=_xll.BDP($A4,G$2)} -> 11.5 | H4: {=_xll.BDP($B4,H$2)} -> 1.46 | I4: {=_xll.BDP($C4,I$2)} -> 0.25 | J4: {=_xll.BDP($D4,J$2)} -> 2.85 | K4: {=_xll.BDP($E4,K$2)} -> 1.02 | M4: 1W | N4: =+G4 -> 11.5 | O4: =G4+H4*0.5+I4 -> 12.48 | P4: =G4-H4*0.5+I4 -> 11.02 | Q4: =G4+J4*0.5+K4 -> 13.945 | R4: =G4-J4*0.5+K4 -> 11.095
A5: USDCLPV2W GFFX Curncy | B5: USDCLP25R2W GFFX Curncy | C5: USDCLP25B2W GFFX Curncy | D5: USDCLP10R2W GFFX Curncy | E5: USDCLP10B2W GFFX Curncy | F5: 2W | G5: {=_xll.BDP($A5,G$2)} -> 12.07 | H5: {=_xll.BDP($B5,H$2)} -> 1.53 | I5: {=_xll.BDP($C5,I$2)} -> 0.26 | J5: {=_xll.BDP($D5,J$2)} -> 2.99 | K5: {=_xll.BDP($E5,K$2)} -> 1.03 | M5: 2W | N5: =+G5 -> 12.07 | O5: =G5+H5*0.5+I5 -> 13.095 | P5: =G5-H5*0.5+I5 -> 11.565 | Q5: =G5+J5*0.5+K5 -> 14.595 | R5: =G5-J5*0.5+K5 -> 11.605
F6: 3W | M6: 3W
A7: USDCLPV1M GFFX Curncy | B7: USDCLP25R1M GFFX Curncy | C7: USDCLP25B1M GFFX Curncy | D7: USDCLP10R1M GFFX Curncy | E7: USDCLP10B1M GFFX Curncy | F7: 1M | G7: {=_xll.BDP($A7,G$2)} -> 12.43 | H7: {=_xll.BDP($B7,H$2)} -> 1.71 | I7: {=_xll.BDP($C7,I$2)} -> 0.27 | J7: {=_xll.BDP($D7,J$2)} -> 3.35 | K7: {=_xll.BDP($E7,K$2)} -> 1.06 | M7: 1M | N7: =+G7 -> 12.43 | O7: =G7+H7*0.5+I7 -> 13.555 | P7: =G7-H7*0.5+I7 -> 11.845 | Q7: =G7+J7*0.5+K7 -> 15.165 | R7: =G7-J7*0.5+K7 -> 11.815
A8: USDCLPV2M GFFX Curncy | B8: USDCLP25R2M GFFX Curncy | C8: USDCLP25B2M GFFX Curncy | D8: USDCLP10R2M GFFX Curncy | E8: USDCLP10B2M GFFX Curncy | F8: 2M | G8: {=_xll.BDP($A8,G$2)} -> 12.5 | H8: {=_xll.BDP($B8,H$2)} -> 1.78 | I8: {=_xll.BDP($C8,I$2)} -> 0.29 | J8: {=_xll.BDP($D8,J$2)} -> 3.49 | K8: {=_xll.BDP($E8,K$2)} -> 1.09 | M8: 2M | N8: =+G8 -> 12.5 | O8: =G8+H8*0.5+I8 -> 13.68 | P8: =G8-H8*0.5+I8 -> 11.9 | Q8: =G8+J8*0.5+K8 -> 15.335 | R8: =G8-J8*0.5+K8 -> 11.845
A9: USDCLPV3M GFFX Curncy | B9: USDCLP25R3M GFFX Curncy | C9: USDCLP25B3M GFFX Curncy | D9: USDCLP10R3M GFFX Curncy | E9: USDCLP10B3M GFFX Curncy | F9: 3M | G9: {=_xll.BDP($A9,G$2)} -> 12.42 | H9: {=_xll.BDP($B9,H$2)} -> 1.85 | I9: {=_xll.BDP($C9,I$2)} -> 0.3 | J9: {=_xll.BDP($D9,J$2)} -> 3.63 | K9: {=_xll.BDP($E9,K$2)} -> 1.13 | M9: 3M | N9: =+G9 -> 12.42 | O9: =G9+H9*0.5+I9 -> 13.645 | P9: =G9-H9*0.5+I9 -> 11.795 | Q9: =G9+J9*0.5+K9 -> 15.365 | R9: =G9-J9*0.5+K9 -> 11.735
F10: 4M | M10: 4M
A11: USDCLPV6M GFFX Curncy | B11: USDCLP25R6M GFFX Curncy | C11: USDCLP25B6M GFFX Curncy | D11: USDCLP10R6M GFFX Curncy | E11: USDCLP10B6M GFFX Curncy | F11: 6M | G11: {=_xll.BDP($A11,G$2)} -> 12.29 | H11: {=_xll.BDP($B11,H$2)} -> 1.94 | I11: {=_xll.BDP($C11,I$2)} -> 0.34 | J11: {=_xll.BDP($D11,J$2)} -> 3.82 | K11: {=_xll.BDP($E11,K$2)} -> 1.24 | M11: 6M | N11: =+G11 -> 12.29 | O11: =G11+H11*0.5+I11 -> 13.6 | P11: =G11-H11*0.5+I11 -> 11.66 | Q11: =G11+J11*0.5+K11 -> 15.44 | R11: =G11-J11*0.5+K11 -> 11.62
A12: USDCLPV9M GFFX Curncy | B12: USDCLP25R9M GFFX Curncy | C12: USDCLP25B9M GFFX Curncy | D12: USDCLP10R9M GFFX Curncy | E12: USDCLP10B9M GFFX Curncy | F12: 9M | G12: {=_xll.BDP($A12,G$2)} -> 12.29 | H12: {=_xll.BDP($B12,H$2)} -> 1.98 | I12: {=_xll.BDP($C12,I$2)} -> 0.37 | J12: {=_xll.BDP($D12,J$2)} -> 3.9 | K12: {=_xll.BDP($E12,K$2)} -> 1.31 | M12: 9M | N12: =+G12 -> 12.29 | O12: =G12+H12*0.5+I12 -> 13.65 | P12: =G12-H12*0.5+I12 -> 11.67 | Q12: =G12+J12*0.5+K12 -> 15.55 | R12: =G12-J12*0.5+K12 -> 11.65
A13: USDCLPV1Y GFFX Curncy | B13: USDCLP25R1Y GFFX Curncy | C13: USDCLP25B1Y GFFX Curncy | D13: USDCLP10R1Y GFFX Curncy | E13: USDCLP10B1Y GFFX Curncy | F13: 1Y | G13: {=_xll.BDP($A13,G$2)} -> 12.3 | H13: {=_xll.BDP($B13,H$2)} -> 2 | I13: {=_xll.BDP($C13,I$2)} -> 0.4 | J13: {=_xll.BDP($D13,J$2)} -> 3.96 | K13: {=_xll.BDP($E13,K$2)} -> 1.37 | M13: 1Y | N13: =+G13 -> 12.3 | O13: =G13+H13*0.5+I13 -> 13.7 | P13: =G13-H13*0.5+I13 -> 11.7 | Q13: =G13+J13*0.5+K13 -> 15.65 | R13: =G13-J13*0.5+K13 -> 11.69
M14: 18M
A15: USDCLPV2Y GFFX Curncy | B15: USDCLP25R2Y GFFX Curncy | C15: USDCLP25B2Y GFFX Curncy | D15: USDCLP10R2Y GFFX Curncy | E15: USDCLP10B2Y GFFX Curncy | F15: 2Y | G15: {=_xll.BDP($A15,G$2)} -> 12.77 | H15: {=_xll.BDP($B15,H$2)} -> 2.01 | I15: {=_xll.BDP($C15,I$2)} -> 0.51 | J15: {=_xll.BDP($D15,J$2)} -> 4.02 | K15: {=_xll.BDP($E15,K$2)} -> 1.62 | M15: 2Y | N15: =+G15 -> 12.77 | O15: =G15+H15*0.5+I15 -> 14.285 | P15: =G15-H15*0.5+I15 -> 12.275 | Q15: =G15+J15*0.5+K15 -> 16.4 | R15: =G15-J15*0.5+K15 -> 12.38
A16: USDCLPV3Y GFFX Curncy | B16: USDCLP25R3Y GFFX Curncy | C16: USDCLP25B3Y GFFX Curncy | D16: USDCLP10R3Y GFFX Curncy | E16: USDCLP10B3Y GFFX Curncy | F16: 3Y | G16: {=_xll.BDP($A16,G$2)} -> 12.64 | H16: {=_xll.BDP($B16,H$2)} -> 2 | I16: {=_xll.BDP($C16,I$2)} -> 0.58 | J16: {=_xll.BDP($D16,J$2)} -> 4.04 | K16: {=_xll.BDP($E16,K$2)} -> 1.8 | M16: 3Y | N16: =+G16 -> 12.64 | O16: =G16+H16*0.5+I16 -> 14.22 | P16: =G16-H16*0.5+I16 -> 12.22 | Q16: =G16+J16*0.5+K16 -> 16.46 | R16: =G16-J16*0.5+K16 -> 12.42
A17: USDCLPV4Y GFFX Curncy | B17: USDCLP25R4Y GFFX Curncy | C17: USDCLP25B4Y GFFX Curncy | D17: USDCLP10R4Y GFFX Curncy | E17: USDCLP10B4Y GFFX Curncy | F17: 4Y | G17: {=_xll.BDP($A17,G$2)} -> 12.62 | H17: {=_xll.BDP($B17,H$2)} -> 1.97 | I17: {=_xll.BDP($C17,I$2)} -> 0.65 | J17: {=_xll.BDP($D17,J$2)} -> 4.03 | K17: {=_xll.BDP($E17,K$2)} -> 2 | M17: 4Y | N17: =+G17 -> 12.62 | O17: =G17+H17*0.5+I17 -> 14.255 | P17: =G17-H17*0.5+I17 -> 12.285 | Q17: =G17+J17*0.5+K17 -> 16.635 | R17: =G17-J17*0.5+K17 -> 12.605
A18: USDCLPV5Y GFFX Curncy | B18: USDCLP25R5Y GFFX Curncy | C18: USDCLP25B5Y GFFX Curncy | D18: USDCLP10R5Y GFFX Curncy | E18: USDCLP10B5Y GFFX Curncy | F18: 5Y | G18: {=_xll.BDP($A18,G$2)} -> 12.6 | H18: {=_xll.BDP($B18,H$2)} -> 1.95 | I18: {=_xll.BDP($C18,I$2)} -> 0.72 | J18: {=_xll.BDP($D18,J$2)} -> 4.05 | K18: {=_xll.BDP($E18,K$2)} -> 2.2 | M18: 5Y | N18: =+G18 -> 12.6 | O18: =G18+H18*0.5+I18 -> 14.295 | P18: =G18-H18*0.5+I18 -> 12.345 | Q18: =G18+J18*0.5+K18 -> 16.825 | R18: =G18-J18*0.5+K18 -> 12.775
A19: USDCLPV7Y GFFX Curncy | B19: USDCLP25R7Y GFFX Curncy | C19: USDCLP25B7Y GFFX Curncy | D19: USDCLP10R7Y GFFX Curncy | E19: USDCLP10B7Y GFFX Curncy | F19: 7Y | G19: {=_xll.BDP($A19,G$2)} -> 12.56 | H19: {=_xll.BDP($B19,H$2)} -> 1.91 | I19: {=_xll.BDP($C19,I$2)} -> 0.79 | J19: {=_xll.BDP($D19,J$2)} -> 4.05 | K19: {=_xll.BDP($E19,K$2)} -> 2.37 | M19: 7Y | N19: =+G19 -> 12.56 | O19: =G19+H19*0.5+I19 -> 14.305 | P19: =G19-H19*0.5+I19 -> 12.395 | Q19: =G19+J19*0.5+K19 -> 16.955 | R19: =G19-J19*0.5+K19 -> 12.905
A20: USDCLPV10Y GFFX Curncy | B20: USDCLP25R10Y GFFX Curncy | C20: USDCLP25B10Y GFFX Curncy | D20: USDCLP10R10Y GFFX Curncy | E20: USDCLP10B10Y GFFX Curncy | F20: 10Y | G20: {=_xll.BDP($A20,G$2)} -> 12.71 | H20: {=_xll.BDP($B20,H$2)} -> 1.96 | I20: {=_xll.BDP($C20,I$2)} -> 0.7 | J20: {=_xll.BDP($D20,J$2)} -> 4.27 | K20: {=_xll.BDP($E20,K$2)} -> 2.56 | M20: 10Y | N20: =+G20 -> 12.71 | O20: =G20+H20*0.5+I20 -> 14.39 | P20: =G20-H20*0.5+I20 -> 12.43 | Q20: =G20+J20*0.5+K20 -> 17.405 | R20: =G20-J20*0.5+K20 -> 13.135
A21: USDCLPV15Y GFFX Curncy | B21: USDCLP25R15Y GFFX Curncy | C21: USDCLP25B15Y GFFX Curncy | D21: USDCLP10R15Y GFFX Curncy | E21: USDCLP10B15Y GFFX Curncy | F21: 15Y | G21: {=_xll.BDP($A21,G$2)} -> 11.55 | H21: {=_xll.BDP($B21,H$2)} -> 1.78 | I21: {=_xll.BDP($C21,I$2)} -> 0.64 | J21: {=_xll.BDP($D21,J$2)} -> 3.88 | K21: {=_xll.BDP($E21,K$2)} -> 2.33 | M21: 15Y | N21: =+G21 -> 11.55 | O21: =G21+H21*0.5+I21 -> 13.08 | P21: =G21-H21*0.5+I21 -> 11.3 | Q21: =G21+J21*0.5+K21 -> 15.82 | R21: =G21-J21*0.5+K21 -> 11.94
T28: 16.746 | U28: 26.694 | V28: 15.439 | W28: 24.471 | X28: =+V28-T28 -> -1.307 | Y28: =+W28-U28 -> -2.223

Sheet FWD pts DEPOs
C1: Points | D1: Points | E1: Points | F1: FWD | G1: FWD | H1: FWD | N1: Points | O1: Points | P1: Points | Q1: FWD | R1: FWD | S1: FWD
B2: Term | C2: Bid | D2: Ask | E2: Mid | F2: Bid | G2: Ask | H2: Mid | M2: Term | N2: Bid | O2: Ask | P2: Mid | Q2: Bid | R2: Ask | S2: Mid
A3: CLP REGN Curncy | B3: SPT | C3: {=_xll.BDP($A3,C$2)} -> 926.3 | D3: {=_xll.BDP($A3,D$2)} -> 927.25 | E3: {=_xll.BDP($A3,E$2)} -> 926.78 | F3: {=_xll.BDP($A3,F$2)} -> 926.3 | G3: {=_xll.BDP($A3,G$2)} -> 927.25 | H3: {=_xll.BDP($A3,H$2)} -> 926.78 | L3: EURCLP BGN Curncy | M3: SPT | N3: {=_xll.BDP($L3,N$2)} -> 1055.61 | O3: {=_xll.BDP($L3,O$2)} -> 1056.68 | P3: {=_xll.BDP($L3,P$2)} -> 1056.15 | Q3: {=_xll.BDP($L3,Q$2)} -> 1055.61 | R3: {=_xll.BDP($L3,R$2)} -> 1056.68 | S3: {=_xll.BDP($L3,S$2)} -> 1056.15
A4: CHNSN BGN Curncy | B4: SN | C4: {=_xll.BDP($A4,C$2)} -> -0.01 | D4: {=_xll.BDP($A4,D$2)} -> -0.01 | E4: {=_xll.BDP($A4,E$2)} -> -0.01 | F4: =C4+F$3 -> 926.29 | G4: =D4+G$3 -> 927.24 | H4: =E4+H$3 -> 926.77 | L4: CHEUN1W BGN Curncy | M4: 1W | N4: {=_xll.BDP($L4,N$2)} -> 0.2124 | O4: {=_xll.BDP($L4,O$2)} -> 0.3082 | P4: {=_xll.BDP($L4,P$2)} -> 0.2603 | Q4: =N4+Q$3 -> 1055.8224 | R4: =O4+R$3 -> 1056.9882 | S4: =P4+S$3 -> 1056.4103
A5: CHN1W BGN Curncy | B5: 1W | C5: {=_xll.BDP($A5,C$2)} -> -0.07 | D5: {=_xll.BDP($A5,D$2)} -> 0.01 | E5: {=_xll.BDP($A5,E$2)} -> -0.03 | F5: =C5+F$3 -> 926.23 | G5: =D5+G$3 -> 927.26 | H5: =E5+H$3 -> 926.75 | L5: CHEUN1M BGN Curncy | M5: 1M | N5: {=_xll.BDP($L5,N$2)} -> 1.1872 | O5: {=_xll.BDP($L5,O$2)} -> 1.3123 | P5: {=_xll.BDP($L5,P$2)} -> 1.2498 | Q5: =N5+Q$3 -> 1056.7972 | R5: =O5+R$3 -> 1057.9923 | S5: =P5+S$3 -> 1057.3998
A6: CHN2W BGN Curncy | B6: 2W | C6: {=_xll.BDP($A6,C$2)} -> -0.09 | D6: {=_xll.BDP($A6,D$2)} -> -0.01 | E6: {=_xll.BDP($A6,E$2)} -> -0.05 | F6: =C6+F$3 -> 926.21 | G6: =D6+G$3 -> 927.24 | H6: =E6+H$3 -> 926.73 | L6: CHEUN2M BGN Curncy | M6: 2M | N6: {=_xll.BDP($L6,N$2)} -> 2.3086 | O6: {=_xll.BDP($L6,O$2)} -> 2.5647 | P6: {=_xll.BDP($L6,P$2)} -> 2.4367 | Q6: =N6+Q$3 -> 1057.9186 | R6: =O6+R$3 -> 1059.2447 | S6: =P6+S$3 -> 1058.5867
A7: CHN3W BGN Curncy | B7: 3W | C7: {=_xll.BDP($A7,C$2)} -> -0.08 | D7: {=_xll.BDP($A7,D$2)} -> -0.03 | E7: {=_xll.BDP($A7,E$2)} -> -0.06 | F7: =C7+F$3 -> 926.22 | G7: =D7+G$3 -> 927.22 | H7: =E7+H$3 -> 926.72 | L7: CHEUN3M BGN Curncy | M7: 3M | N7: {=_xll.BDP($L7,N$2)} -> 3.3116 | O7: {=_xll.BDP($L7,O$2)} -> 3.5493 | P7: {=_xll.BDP($L7,P$2)} -> 3.4305 | Q7: =N7+Q$3 -> 1058.9216 | R7: =O7+R$3 -> 1060.2293 | S7: =P7+S$3 -> 1059.5805
A8: CHN1M BGN Curncy | B8: 1M | C8: {=_xll.BDP($A8,C$2)} -> -0.12 | D8: {=_xll.BDP($A8,D$2)} -> -0.02 | E8: {=_xll.BDP($A8,E$2)} -> -0.07 | F8: =C8+F$3 -> 926.18 | G8: =D8+G$3 -> 927.23 | H8: =E8+H$3 -> 926.71 | L8: CHEUN4M BGN Curncy | M8: 4M | N8: {=_xll.BDP($L8,N$2)} -> 4.3254 | O8: {=_xll.BDP($L8,O$2)} -> 4.6053 | P8: {=_xll.BDP($L8,P$2)} -> 4.4653 | Q8: =N8+Q$3 -> 1059.9354 | R8: =O8+R$3 -> 1061.2853 | S8: =P8+S$3 -> 1060.6153
A9: CHN2M BGN Curncy | B9: 2M | C9: {=_xll.BDP($A9,C$2)} -> -0.33 | D9: {=_xll.BDP($A9,D$2)} -> -0.13 | E9: {=_xll.BDP($A9,E$2)} -> -0.23 | F9: =C9+F$3 -> 925.97 | G9: =D9+G$3 -> 927.12 | H9: =E9+H$3 -> 926.55 | L9: CHEUN5M BGN Curncy | M9: 5M | N9: {=_xll.BDP($L9,N$2)} -> 5.3261 | O9: {=_xll.BDP($L9,O$2)} -> 5.5423 | P9: {=_xll.BDP($L9,P$2)} -> 5.4342 | Q9: =N9+Q$3 -> 1060.9361 | R9: =O9+R$3 -> 1062.2223 | S9: =P9+S$3 -> 1061.5842
A10: CHN3M BGN Curncy | B10: 3M | C10: {=_xll.BDP($A10,C$2)} -> -0.49 | D10: {=_xll.BDP($A10,D$2)} -> -0.31 | E10: {=_xll.BDP($A10,E$2)} -> -0.4 | F10: =C10+F$3 -> 925.81 | G10: =D10+G$3 -> 926.94 | H10: =E10+H$3 -> 926.38 | L10: CHEUN6M BGN Curncy | M10: 6M | N10: {=_xll.BDP($L10,N$2)} -> 6.2564 | O10: {=_xll.BDP($L10,O$2)} -> 6.5527 | P10: {=_xll.BDP($L10,P$2)} -> 6.4046 | Q10: =N10+Q$3 -> 1061.8664 | R10: =O10+R$3 -> 1063.2327 | S10: =P10+S$3 -> 1062.5546
A11: CHN4M BGN Curncy | B11: 4M | C11: {=_xll.BDP($A11,C$2)} -> -0.7 | D11: {=_xll.BDP($A11,D$2)} -> -0.5 | E11: {=_xll.BDP($A11,E$2)} -> -0.6 | F11: =C11+F$3 -> 925.6 | G11: =D11+G$3 -> 926.75 | H11: =E11+H$3 -> 926.18 | L11: CHEUN9M BGN Curncy | M11: 9M | N11: {=_xll.BDP($L11,N$2)} -> 9.2168 | O11: {=_xll.BDP($L11,O$2)} -> 9.8691 | P11: {=_xll.BDP($L11,P$2)} -> 9.5429 | Q11: =N11+Q$3 -> 1064.8268 | R11: =O11+R$3 -> 1066.5491 | S11: =P11+S$3 -> 1065.6929
A12: CHN5M BGN Curncy | B12: 5M | C12: {=_xll.BDP($A12,C$2)} -> -0.94 | D12: {=_xll.BDP($A12,D$2)} -> -0.8 | E12: {=_xll.BDP($A12,E$2)} -> -0.87 | F12: =C12+F$3 -> 925.36 | G12: =D12+G$3 -> 926.45 | H12: =E12+H$3 -> 925.91 | L12: CHEUN12M BGN Curncy | M12: 1Y | N12: {=_xll.BDP($L12,N$2)} -> 12.8929 | O12: {=_xll.BDP($L12,O$2)} -> 13.4988 | P12: {=_xll.BDP($L12,P$2)} -> 13.1959 | Q12: =N12+Q$3 -> 1068.5029 | R12: =O12+R$3 -> 1070.1788 | S12: =P12+S$3 -> 1069.3459
A13: CHN6M BGN Curncy | B13: 6M | C13: {=_xll.BDP($A13,C$2)} -> -1.29 | D13: {=_xll.BDP($A13,D$2)} -> -1.08 | E13: {=_xll.BDP($A13,E$2)} -> -1.18 | F13: =C13+F$3 -> 925.01 | G13: =D13+G$3 -> 926.17 | H13: =E13+H$3 -> 925.6 | L13: CHEUN2Y BGN Curncy | M13: 2Y | N13: {=_xll.BDP($L13,N$2)} -> 29.5257 | O13: {=_xll.BDP($L13,O$2)} -> 32.1502 | P13: {=_xll.BDP($L13,P$2)} -> 30.8379 | Q13: =N13+Q$3 -> 1085.1357 | R13: =O13+R$3 -> 1088.8302 | S13: =P13+S$3 -> 1086.9879
A14: CHN7M BGN Curncy | B14: 6M | C14: {=_xll.BDP($A14,C$2)} -> -1.49 | D14: {=_xll.BDP($A14,D$2)} -> -1.18 | E14: {=_xll.BDP($A14,E$2)} -> -1.34 | F14: =C14+F$3 -> 924.81 | G14: =D14+G$3 -> 926.07 | H14: =E14+H$3 -> 925.44 | L14: CHEUN3Y BGN Curncy | M14: 3Y | N14: {=_xll.BDP($L14,N$2)} -> 48.4618 | O14: {=_xll.BDP($L14,O$2)} -> 52.7113 | P14: {=_xll.BDP($L14,P$2)} -> 50.5866 | Q14: =N14+Q$3 -> 1104.0718 | R14: =O14+R$3 -> 1109.3913 | S14: =P14+S$3 -> 1106.7366
A15: CHN8M BGN Curncy | B15: 6M | C15: {=_xll.BDP($A15,C$2)} -> -1.72 | D15: {=_xll.BDP($A15,D$2)} -> -1.31 | E15: {=_xll.BDP($A15,E$2)} -> -1.51 | F15: =C15+F$3 -> 924.58 | G15: =D15+G$3 -> 925.94 | H15: =E15+H$3 -> 925.27 | L15: CHEUN4Y BGN Curncy | M15: 4Y | N15: {=_xll.BDP($L15,N$2)} -> 64.2643 | O15: {=_xll.BDP($L15,O$2)} -> 67.1016 | P15: {=_xll.BDP($L15,P$2)} -> 65.683 | Q15: =N15+Q$3 -> 1119.8743 | R15: =O15+R$3 -> 1123.7816 | S15: =P15+S$3 -> 1121.833
A16: CHN9M BGN Curncy | B16: 9M | C16: {=_xll.BDP($A16,C$2)} -> -1.92 | D16: {=_xll.BDP($A16,D$2)} -> -1.48 | E16: {=_xll.BDP($A16,E$2)} -> -1.7 | F16: =C16+F$3 -> 924.38 | G16: =D16+G$3 -> 925.77 | H16: =E16+H$3 -> 925.08 | L16: CHEUN5Y BGN Curncy | M16: 5Y | N16: {=_xll.BDP($L16,N$2)} -> 104.8433 | O16: {=_xll.BDP($L16,O$2)} -> 111.8485 | P16: {=_xll.BDP($L16,P$2)} -> 108.3459 | Q16: =N16+Q$3 -> 1160.4533 | R16: =O16+R$3 -> 1168.5285 | S16: =P16+S$3 -> 1164.4959
A17: CHN10M BGN Curncy | B17: 9M | C17: {=_xll.BDP($A17,C$2)} -> -1.97 | D17: {=_xll.BDP($A17,D$2)} -> -1.56 | E17: {=_xll.BDP($A17,E$2)} -> -1.76 | F17: =C17+F$3 -> 924.33 | G17: =D17+G$3 -> 925.69 | H17: =E17+H$3 -> 925.02
A18: CHN11M BGN Curncy | B18: 9M | C18: {=_xll.BDP($A18,C$2)} -> -2.03 | D18: {=_xll.BDP($A18,D$2)} -> -1.62 | E18: {=_xll.BDP($A18,E$2)} -> -1.83 | F18: =C18+F$3 -> 924.27 | G18: =D18+G$3 -> 925.63 | H18: =E18+H$3 -> 924.95
A19: CHN12M BGN Curncy | B19: 12M | C19: {=_xll.BDP($A19,C$2)} -> -2.03 | D19: {=_xll.BDP($A19,D$2)} -> -1.63 | E19: {=_xll.BDP($A19,E$2)} -> -1.83 | F19: =C19+F$3 -> 924.27 | G19: =D19+G$3 -> 925.62 | H19: =E19+H$3 -> 924.95
A20: CHN18M BGN Curncy | B20: 18M | C20: {=_xll.BDP($A20,C$2)} -> -2.18 | D20: {=_xll.BDP($A20,D$2)} -> -1.58 | E20: {=_xll.BDP($A20,E$2)} -> -1.88 | F20: =C20+F$3 -> 924.12 | G20: =D20+G$3 -> 925.67 | H20: =E20+H$3 -> 924.9
A21: CHN2Y BGN Curncy | B21: 2Y | C21: {=_xll.BDP($A21,C$2)} -> -0.52 | D21: {=_xll.BDP($A21,D$2)} -> 1.3 | E21: {=_xll.BDP($A21,E$2)} -> 0.39 | F21: =C21+F$3 -> 925.78 | G21: =D21+G$3 -> 928.55 | H21: =E21+H$3 -> 927.17
A22: CHN3Y BGN Curncy | B22: 3Y | C22: {=_xll.BDP($A22,C$2)} -> 3.29 | D22: {=_xll.BDP($A22,D$2)} -> 6.32 | E22: {=_xll.BDP($A22,E$2)} -> 4.8 | F22: =C22+F$3 -> 929.59 | G22: =D22+G$3 -> 933.57 | H22: =E22+H$3 -> 931.58
A23: CHN4Y BGN Curncy | B23: 4Y | C23: {=_xll.BDP($A23,C$2)} -> 4.92 | D23: {=_xll.BDP($A23,D$2)} -> 6.55 | E23: {=_xll.BDP($A23,E$2)} -> 5.74 | F23: =C23+F$3 -> 931.22 | G23: =D23+G$3 -> 933.8 | H23: =E23+H$3 -> 932.52
A24: CHN5Y BGN Curncy | B24: 5Y | C24: {=_xll.BDP($A24,C$2)} -> 26.9 | D24: {=_xll.BDP($A24,D$2)} -> 31.71 | E24: {=_xll.BDP($A24,E$2)} -> 29.31 | F24: =C24+F$3 -> 953.2 | G24: =D24+G$3 -> 958.96 | H24: =E24+H$3 -> 956.09
I27: Implied | T27: Implied
B28: =TODAY() -> 46217 | G28: CLP Rate | H28: =H3 -> 926.78 | I28: USD Rate | S28: =S3 -> 1056.15 | T28: EUR Rate
A29: IRS CLPCAM | B29: Maturity | C29: Dias | D29: Años | E29: Bid | F29: Ask | G29: Mid | H29: FWD | I29: Mid | Q29: Maturity | R29: Años | S29: FWD | T29: Mid
A30: CHIBPROM Index | B30: 1d | C30: 1 | E30: =_xll.BDP($A30, "bid") -> 4.5 | F30: =_xll.BDP($A30, "ask") -> 4.5 | G30: =_xll.BDP($A30, "mid") -> 4.5 | H30: =H4 -> 926.77 | I30: =(H$28/H30*(1+G30*C30/36000)-1)*36000/C30 -> 4.8884944
A31: CHSWPA Curncy | B31: {=_xll.BDP(A31, "maturity")} -> 20-08-2026 | C31: =B31-$B$28 -> 37 | D31: =YEARFRAC($B$28,B31,1) -> 0.10136986 | E31: {=_xll.BDP($A31, "bid")} -> 4.4917 | F31: {=_xll.BDP($A31, "ask")} -> 4.5183 | G31: {=_xll.BDP($A31, "mid")} -> 4.505 | H31: =H8 -> 926.71 | I31: =(H$28/H31*(1+G31*C31/36000)-1)*36000/C31 -> 4.5788348 | Q31: =+B31 -> 20-08-2026 | R31: =+D31 -> 0.10136986 | S31: =+S5 -> 1057.3998 | T31: =(S$28/S31*(1+G31*C31/36000)-1)*36000/C31 -> 3.3496641
A32: CHSWPB Curncy | B32: {=_xll.BDP(A32, "maturity")} -> 20-09-2026 | C32: =B32-$B$28 -> 68 | D32: =YEARFRAC($B$28,B32,1) -> 0.18630137 | E32: =_xll.BDP($A32, "bid") -> 4.4986 | F32: =_xll.BDP($A32, "ask") -> 4.5314 | G32: =_xll.BDP($A32, "mid") -> 4.515 | H32: =H9 -> 926.55 | I32: =(H$28/H32*(1+G32*C32/36000)-1)*36000/C32 -> 4.6475381 | Q32: =+B32 -> 20-09-2026 | R32: =+D32 -> 0.18630137 | S32: =+S6 -> 1058.5867 | T32: =(S$28/S32*(1+G32*C32/36000)-1)*36000/C32 -> 3.2859846
A33: CHSWPC Curncy | B33: {=_xll.BDP(A33, "maturity")} -> 20-10-2026 | C33: =B33-$B$28 -> 98 | D33: =YEARFRAC($B$28,B33,1) -> 0.26849315 | E33: =_xll.BDP($A33, "bid") -> 4.4944 | F33: =_xll.BDP($A33, "ask") -> 4.5256 | G33: =_xll.BDP($A33, "mid") -> 4.51 | H33: =H10 -> 926.38 | I33: =(H$28/H33*(1+G33*C33/36000)-1)*36000/C33 -> 4.6705635 | Q33: =+B33 -> 20-10-2026 | R33: =+D33 -> 0.26849315 | S33: =+S7 -> 1059.5805 | T33: =(S$28/S33*(1+G33*C33/36000)-1)*36000/C33 -> 3.3060752
A34: CHSWPD Curncy | B34: {=_xll.BDP(A34, "maturity")} -> 20-11-2026 | C34: =B34-$B$28 -> 129 | D34: =YEARFRAC($B$28,B34,1) -> 0.35342466 | E34: =_xll.BDP($A34, "bid") -> 4.495 | F34: =_xll.BDP($A34, "ask") -> 4.529 | G34: =_xll.BDP($A34, "mid") -> 4.512 | H34: =H11 -> 926.18 | I34: =(H$28/H34*(1+G34*C34/36000)-1)*36000/C34 -> 4.6957106 | Q34: =+B34 -> 20-11-2026 | R34: =+D34 -> 0.35342466 | S34: =+S8 -> 1060.6153 | T34: =(S$28/S34*(1+G34*C34/36000)-1)*36000/C34 -> 3.3180915
A35: CHSWPE Curncy | B35: {=_xll.BDP(A35, "maturity")} -> 20-12-2026 | C35: =B35-$B$28 -> 159 | D35: =YEARFRAC($B$28,B35,1) -> 0.43561644 | E35: =_xll.BDP($A35, "bid") -> 4.503 | F35: =_xll.BDP($A35, "ask") -> 4.523 | G35: =_xll.BDP($A35, "mid") -> 4.513 | H35: =H12 -> 925.91 | I35: =(H$28/H35*(1+G35*C35/36000)-1)*36000/C35 -> 4.7299838 | Q35: =+B35 -> 20-12-2026 | R35: =+D35 -> 0.43561644 | S35: =+S9 -> 1061.5842 | T35: =(S$28/S35*(1+G35*C35/36000)-1)*36000/C35 -> 3.3308899
A36: CHSWPF Curncy | B36: {=_xll.BDP(A36, "maturity")} -> 20-01-2027 | C36: =B36-$B$28 -> 190 | D36: =YEARFRAC($B$28,B36,1) -> 0.52054795 | E36: =_xll.BDP($A36, "bid") -> 4.4987 | F36: =_xll.BDP($A36, "ask") -> 4.5313 | G36: =_xll.BDP($A36, "mid") -> 4.515 | H36: =H13 -> 925.6 | I36: =(H$28/H36*(1+G36*C36/36000)-1)*36000/C36 -> 4.7623062 | Q36: =+B36 -> 20-01-2027 | R36: =+D36 -> 0.52054795 | S36: =S10 -> 1062.5546 | T36: =(S$28/S36*(1+G36*C36/36000)-1)*36000/C36 -> 3.3457237
A37: CHSWPG Curncy | B37: {=_xll.BDP(A37, "maturity")} -> 20-02-2027 | C37: =B37-$B$28 -> 221 | D37: =YEARFRAC($B$28,B37,1) -> 0.60547945 | E37: =_xll.BDP($A37, "bid") -> 4.506 | F37: =_xll.BDP($A37, "ask") -> 4.526 | G37: =_xll.BDP($A37, "mid") -> 4.516 | H37: =H14 -> 925.44 | I37: =(H$28/H37*(1+G37*C37/36000)-1)*36000/C37 -> 4.7584058
A38: CHSWPH Curncy | B38: {=_xll.BDP(A38, "maturity")} -> 20-03-2027 | C38: =B38-$B$28 -> 249 | D38: =YEARFRAC($B$28,B38,1) -> 0.68219178 | E38: =_xll.BDP($A38, "bid") -> 4.514 | F38: =_xll.BDP($A38, "ask") -> 4.536 | G38: =_xll.BDP($A38, "mid") -> 4.525 | H38: =H15 -> 925.27 | I38: =(H$28/H38*(1+G38*C38/36000)-1)*36000/C38 -> 4.7683301
A39: CHSWPI Curncy | B39: {=_xll.BDP(A39, "maturity")} -> 20-04-2027 | C39: =B39-$B$28 -> 280 | D39: =YEARFRAC($B$28,B39,1) -> 0.76712329 | E39: =_xll.BDP($A39, "bid") -> 4.5065 | F39: =_xll.BDP($A39, "ask") -> 4.5435 | G39: =_xll.BDP($A39, "mid") -> 4.525 | H39: =H16 -> 925.08 | I39: =(H$28/H39*(1+G39*C39/36000)-1)*36000/C39 -> 4.7695885 | Q39: =+B39 -> 20-04-2027 | R39: =+D39 -> 0.76712329 | S39: =+S11 -> 1065.6929 | T39: =(S$28/S39*(1+G39*C39/36000)-1)*36000/C39 -> 3.3331689
A40: CHSWPJ Curncy | B40: {=_xll.BDP(A40, "maturity")} -> 20-05-2027 | C40: =B40-$B$28 -> 310 | D40: =YEARFRAC($B$28,B40,1) -> 0.84931507 | E40: =_xll.BDP($A40, "bid") -> 4.5066 | F40: =_xll.BDP($A40, "ask") -> 4.5354 | G40: =_xll.BDP($A40, "mid") -> 4.521 | H40: =H17 -> 925.02 | I40: =(H$28/H40*(1+G40*C40/36000)-1)*36000/C40 -> 4.7505562
A41: CHSWPK Curncy | B41: {=_xll.BDP(A41, "maturity")} -> 20-06-2027 | C41: =B41-$B$28 -> 341 | D41: =YEARFRAC($B$28,B41,1) -> 0.93424658 | E41: =_xll.BDP($A41, "bid") -> 4.5126 | F41: =_xll.BDP($A41, "ask") -> 4.5334 | G41: =_xll.BDP($A41, "mid") -> 4.523 | H41: =H18 -> 924.95 | I41: =(H$28/H41*(1+G41*C41/36000)-1)*36000/C41 -> 4.740821
A42: CHSWP1 Curncy | B42: {=_xll.BDP(A42, "maturity")} -> 20-07-2027 | C42: =B42-$B$28 -> 371 | D42: =YEARFRAC($B$28,B42,1) -> 1.0164384 | E42: =_xll.BDP($A42, "bid") -> 4.5412 | F42: =_xll.BDP($A42, "ask") -> 4.5788 | G42: =_xll.BDP($A42, "mid") -> 4.56 | H42: =H19 -> 924.95 | I42: =(H$28/H42*(1+G42*C42/36000)-1)*36000/C42 -> 4.7610043 | Q42: =+B42 -> 20-07-2027 | R42: =+D42 -> 1.0164384 | S42: =+S12 -> 1069.3459 | T42: =(S$28/S42*(1+G42*C42/36000)-1)*36000/C42 -> 3.3063009
...

Sheet EURUSD
C1: Points | D1: Points | E1: Points | F1: FWD | G1: FWD | H1: FWD
B2: Term | C2: Bid | D2: Ask | E2: Mid | F2: Bid | G2: Ask | H2: Mid
A4: EURON BGN Curncy | B4: ON | C4: {=_xll.BDP($A4,C$2)} -> 0.414 | D4: {=_xll.BDP($A4,D$2)} -> 0.446 | E4: {=_xll.BDP($A4,E$2)} -> 0.43 | F4: =F$6-C4/10000 -> 1.1435586 | G4: =G$6-D4/10000 -> 1.1435554 | H4: =H$6-E4/10000 -> 1.143557
A5: EURTN BGN Curncy | B5: TN | C5: {=_xll.BDP($A5,C$2)} -> 0.438 | D5: {=_xll.BDP($A5,D$2)} -> 0.451 | E5: {=_xll.BDP($A5,E$2)} -> 0.445 | F5: =F$6-C5/10000 -> 1.1435562 | G5: =G$6-D5/10000 -> 1.1435549 | H5: =H$6-E5/10000 -> 1.1435555
A6: EUR BGN Curncy | B6: SP | F6: {=_xll.BDP($A6,C$2)} -> 1.1436 | G6: {=_xll.BDP($A6,D$2)} -> 1.1436 | H6: {=_xll.BDP($A6,E$2)} -> 1.1436
A7: EURSN BGN Curncy | B7: SN | C7: {=_xll.BDP($A7,C$2)} -> 1.342 | D7: {=_xll.BDP($A7,D$2)} -> 1.361 | E7: {=_xll.BDP($A7,E$2)} -> 1.352 | F7: =F$6+C7/10000 -> 1.1437342 | G7: =G$6+D7/10000 -> 1.1437361 | H7: =H$6+E7/10000 -> 1.1437352
A8: EUR1W BGN Curncy | B8: 1W | C8: {=_xll.BDP($A8,C$2)} -> 3.15 | D8: {=_xll.BDP($A8,D$2)} -> 3.19 | E8: {=_xll.BDP($A8,E$2)} -> 3.17 | F8: =F$6+C8/10000 -> 1.143915 | G8: =G$6+D8/10000 -> 1.143919 | H8: =H$6+E8/10000 -> 1.143917
A9: EURMAR BGN Curncy | B9: MAR | C9: {=_xll.BDP($A9,C$2)} -> 117.02 | D9: {=_xll.BDP($A9,D$2)} -> 118.02 | E9: {=_xll.BDP($A9,E$2)} -> 117.52 | F9: =F$6+C9/10000 -> 1.155302 | G9: =G$6+D9/10000 -> 1.155402 | H9: =H$6+E9/10000 -> 1.155352
A10: EURMB4 BGN Curncy | B10: BAPR | C10: {=_xll.BDP($A10,C$2)} -> 117.48 | D10: {=_xll.BDP($A10,D$2)} -> 118.48 | E10: {=_xll.BDP($A10,E$2)} -> 117.98 | F10: =F$6+C10/10000 -> 1.155348 | G10: =G$6+D10/10000 -> 1.155448 | H10: =H$6+E10/10000 -> 1.155398
A11: EUR1M BGN Curncy | B11: 1M | C11: {=_xll.BDP($A11,C$2)} -> 14.26 | D11: {=_xll.BDP($A11,D$2)} -> 14.36 | E11: {=_xll.BDP($A11,E$2)} -> 14.31 | F11: =F$6+C11/10000 -> 1.145026 | G11: =G$6+D11/10000 -> 1.145036 | H11: =H$6+E11/10000 -> 1.145031
A12: EUR2M BGN Curncy | B12: 2M | C12: {=_xll.BDP($A12,C$2)} -> 28.59 | D12: {=_xll.BDP($A12,D$2)} -> 28.86 | E12: {=_xll.BDP($A12,E$2)} -> 28.73 | F12: =F$6+C12/10000 -> 1.146459 | G12: =G$6+D12/10000 -> 1.146486 | H12: =H$6+E12/10000 -> 1.146473
A13: EUR3M BGN Curncy | B13: 3M | C13: {=_xll.BDP($A13,C$2)} -> 42.74 | D13: {=_xll.BDP($A13,D$2)} -> 43.04 | E13: {=_xll.BDP($A13,E$2)} -> 42.89 | F13: =F$6+C13/10000 -> 1.147874 | G13: =G$6+D13/10000 -> 1.147904 | H13: =H$6+E13/10000 -> 1.147889
A14: EURJUN BGN Curncy | B14: JUN | C14: {=_xll.BDP($A14,C$2)} -> 158.05 | D14: {=_xll.BDP($A14,D$2)} -> 159.05 | E14: {=_xll.BDP($A14,E$2)} -> 158.55 | F14: =F$6+C14/10000 -> 1.159405 | G14: =G$6+D14/10000 -> 1.159505 | H14: =H$6+E14/10000 -> 1.159455
A15: EURMB7 BGN Curncy | B15: BJUL | C15: {=_xll.BDP($A15,C$2)} -> 158.53 | D15: {=_xll.BDP($A15,D$2)} -> 159.53 | E15: {=_xll.BDP($A15,E$2)} -> 159.03 | F15: =F$6+C15/10000 -> 1.159453 | G15: =G$6+D15/10000 -> 1.159553 | H15: =H$6+E15/10000 -> 1.159503
A16: EUR4M BGN Curncy | B16: 4M | C16: {=_xll.BDP($A16,C$2)} -> 55.42 | D16: {=_xll.BDP($A16,D$2)} -> 55.91 | E16: {=_xll.BDP($A16,E$2)} -> 55.66 | F16: =F$6+C16/10000 -> 1.149142 | G16: =G$6+D16/10000 -> 1.149191 | H16: =H$6+E16/10000 -> 1.149166
A17: EUR5M BGN Curncy | B17: 5M | C17: {=_xll.BDP($A17,C$2)} -> 68.63 | D17: {=_xll.BDP($A17,D$2)} -> 69.17 | E17: {=_xll.BDP($A17,E$2)} -> 68.9 | F17: =F$6+C17/10000 -> 1.150463 | G17: =G$6+D17/10000 -> 1.150517 | H17: =H$6+E17/10000 -> 1.15049
A18: EUR6M BGN Curncy | B18: 6M | C18: {=_xll.BDP($A18,C$2)} -> 84.54 | D18: {=_xll.BDP($A18,D$2)} -> 85.04 | E18: {=_xll.BDP($A18,E$2)} -> 84.79 | F18: =F$6+C18/10000 -> 1.152054 | G18: =G$6+D18/10000 -> 1.152104 | H18: =H$6+E18/10000 -> 1.152079
... A28: EUR5Y BGN Curncy | B28: 5Y | C28: {=_xll.BDP($A28,C$2)} -> 777.05 | D28: {=_xll.BDP($A28,D$2)} -> 787.95 | E28: {=_xll.BDP($A28,E$2)} -> 782.5 | F28: =F$6+C28/10000 -> 1.221305 | G28: =G$6+D28/10000 -> 1.222395 | H28: =H$6+E28/10000 -> 1.22185
